<?xml version="1.0"?>
<robot xmlns:xacro="http://www.ros.org/wiki/xacro">
 
  <xacro:include filename="$(find franka_description)/robots/panda_hand/panda_hand.gazebo.xacro"/>
  <xacro:include filename="$(find franka_description)/robots/panda_hand/panda_hand.transmission.xacro"/>

  <xacro:property name="joint_lower_limit" value="0.0" />
  <xacro:property name="joint_upper_limit" value="0.055" />

  <xacro:macro name="panda_hand" params="robot_name hardware_interface first_link_name">
    <link name="${first_link_name}">
      <inertial>
        <mass value="0.73" />
        <origin xyz="0 0.0015244 0.0275912" rpy="0 0 0" />
        <inertia ixx="0.00278560230025" ixy="0.0" ixz="0.0" iyy="0.000400033405336" iyz="0.0" izz="0.00256378041832" />
      </inertial>
      <visual>
        <origin xyz="0 0 0" rpy="0 0 0"/>
        <geometry>
          <mesh filename="package://franka_description/meshes/panda_hand/visual/hand.dae"/>
        </geometry>
        <material name="">
          <color rgba="1 1 1 1"/>
        </material>
      </visual>
      <collision>
        <origin xyz="0 0 0" rpy="0 0 0"/>
        <geometry>
          <mesh filename="package://franka_description/meshes/panda_hand/collision/hand.stl"/>
        </geometry>
      </collision>
    </link>

    <joint name="${robot_name}_finger_joint1" type="prismatic">
      <parent link="${robot_name}_hand"/>
      <child link="${robot_name}_leftfinger"/>
      <origin xyz="0 0 0.0584" rpy="0 0 0"/>
      <axis xyz="0 1 0"/>      
      <limit effort="500.0" lower="${joint_lower_limit}" upper="${joint_upper_limit}" velocity="2.0"/>          
    </joint>

    <link name="${robot_name}_leftfinger">
      <inertial>
        <mass value="0.1" />
        <origin xyz="0 0.0145644 0.0227941" rpy="0 0 0" />
        <inertia ixx="3.01220925051e-05" ixy="0.0" ixz="0.0" iyy="2.95873808038e-05" iyz="0.0" izz="6.95125211657e-06" />
      </inertial>
      <visual>
        <origin xyz="0 0 0" rpy="0 0 0"/>
        <geometry>
          <mesh filename="package://franka_description/meshes/panda_hand/visual/finger.dae"/>
        </geometry>
        <material name="">
          <color rgba="1 1 1 1"/>
        </material>
      </visual>
      <collision>
        <origin xyz="0 0 0" rpy="0 0 0"/>
        <geometry>
          <mesh filename="package://franka_description/meshes/panda_hand/collision/finger.stl"/>
        </geometry>
      </collision>
    </link>

    <joint name="${robot_name}_finger_joint2" type="prismatic">
      <parent link="${robot_name}_hand"/>
      <child link="${robot_name}_rightfinger"/>
      <origin xyz="0 0 0.0584" rpy="0 0 0"/>
      <axis xyz="0 -1 0"/>
      <limit effort="500.0" lower="${joint_lower_limit}" upper="${joint_upper_limit}" velocity="2.0"/>
    </joint>

    <link name="${robot_name}_rightfinger">
      <inertial>
        <mass value="0.1" />
        <origin xyz="0 0.0145644 0.0227941" rpy="0 0 ${pi}" />
        <inertia ixx="3.01220925051e-05" ixy="0.0" ixz="0.0" iyy="2.95873808038e-05" iyz="0.0" izz="6.95125211657e-06" />
      </inertial>
      <visual>
        <origin xyz="0 0 0" rpy="0 0 ${pi}"/>
        <geometry>
          <mesh filename="package://franka_description/meshes/panda_hand/visual/finger.dae"/>
        </geometry>
        <material name="">
          <color rgba="1 1 1 1"/>
        </material>
      </visual>
      <collision>
        <origin xyz="0 0 0" rpy="0 0 ${pi}"/>
        <geometry>
          <mesh filename="package://franka_description/meshes/panda_hand/collision/finger.stl"/>
        </geometry>
      </collision>
    </link>

    <xacro:panda_hand_gazebo robot_name="${robot_name}" />
    <xacro:panda_hand_transmission hardware_interface="${hardware_interface}" robot_name="${robot_name}"/>
  </xacro:macro>

</robot>
