<?xml version="1.0"?>
<robot xmlns:xacro="http://www.ros.org/wiki/xacro">

  <!-- Import all Gazebo-customization elements, including Gazebo colors -->
  <xacro:include filename="$(find franka_description)/robots/panda_arm/panda_arm.gazebo.xacro" />
  <!-- Import Transmissions -->
  <xacro:include filename="$(find franka_description)/robots/panda_arm/panda_arm.transmission.xacro" />

  <!-- some constants -->
  <xacro:property name="description_pkg" value="franka_description" />
  <xacro:property name="collision_folder" value="approximated" />
  <!-- <xacro:property name="collision_folder" value="accurate" /> -->
  <xacro:property name="safety_controller_k_pos" value="100" />
  <xacro:property name="safety_controller_k_vel" value="2" />
  <xacro:property name="joint_damping" value="0.5" />

  <!-- TODO: set the correct individual effort values for every joint -->
  <xacro:property name="max_effort" value="300"/>

  <xacro:macro name="panda_arm" params="hand_link_name=:'' robot_name parent hardware_interface *origin">

    <!--joint between {parent} and link_0-->
    <joint name="${robot_name}_joint0" type="fixed">
      <xacro:insert_block name="origin"/>
      <parent link="${parent}"/>
      <child link="${robot_name}_link0"/>
    </joint>

    <link name="${robot_name}_link0">
      <visual>
        <geometry>
          <mesh filename="package://${description_pkg}/meshes/panda_arm/visual/link0.dae"/>
        </geometry>
        <material name="">
          <color rgba="1 1 1 1"/>
        </material>        
      </visual>
      <collision>
        <geometry>
          <mesh filename="package://${description_pkg}/meshes/panda_arm/collision/${collision_folder}/link0.stl"/>
        </geometry>
      </collision>

      <inertial>
        <mass value="2.92" />
        <origin xyz="-0.025566 -2.88e-05 0.057332" rpy="0 0 0" />
        <inertia ixx="0.00782229414331" ixy="-1.56191622996e-05" ixz="-0.00126005738123" iyy="0.0109027971813" iyz="1.08233858202e-05" izz="0.0102355503949" />
      </inertial>
    </link>

    <!-- joint between link_0 and link_1 -->
    <joint name="${robot_name}_joint1" type="revolute">
      <parent link="${robot_name}_link0"/>
      <child link="${robot_name}_link1"/>
      <origin rpy="0 0 0" xyz="0 0 0.333"/>
      <axis xyz="0 0 1"/>
      <limit lower="${-165 * pi / 180}" upper="${165 * pi / 180}"
             effort="${max_effort}" velocity="${124 * pi / 180}" />
      <safety_controller soft_lower_limit="${-160 * pi / 180}"
                         soft_upper_limit="${160 * pi / 180}"
                         k_position="${safety_controller_k_pos}"
                         k_velocity="${safety_controller_k_vel}"/>
      <dynamics damping="${joint_damping}"/>
    </joint>

    <link name="${robot_name}_link1">
      <inertial>
        <mass value="2.74" />
        <origin xyz="0 -0.06861 0.0322285" rpy="0 0 0" />
        <inertia ixx="0.0182856182281" ixy="0.0" ixz="0.0" iyy="0.00621358421175" iyz="-0.00472844221905" izz="0.0161514346309" />
      </inertial>
      <visual>
        <geometry>
          <mesh filename="package://${description_pkg}/meshes/panda_arm/visual/link1.dae"/>
        </geometry>
        <material name="">
          <color rgba="1 1 1 1"/>
        </material>        
      </visual>
      <collision>
        <geometry>
          <mesh filename="package://${description_pkg}/meshes/panda_arm/collision/${collision_folder}/link1.stl"/>
        </geometry>
      </collision>
    </link>

    <joint name="${robot_name}_joint2" type="revolute">
      <parent link="${robot_name}_link1"/>
      <child link="${robot_name}_link2"/>
      <origin rpy="${-pi/2} 0 0" xyz="0 0 0"/>
      <axis xyz="0 0 1"/>
      <limit lower="${-101 * pi / 180}" upper="${101 * pi / 180}"
             effort="${max_effort}" velocity="${124 * pi / 180}" />
      <safety_controller soft_lower_limit="${-99 * pi / 180}"
                         soft_upper_limit="${99 * pi / 180}"
                         k_position="${safety_controller_k_pos}"
                         k_velocity="${safety_controller_k_vel}"/>
      <dynamics damping="${joint_damping}"/>
    </joint>

    <link name="${robot_name}_link2">
      <inertial>
        <mass value="2.74" />
        <origin xyz="0 -0.06861 0.0322285" rpy="0 0 0" />
        <inertia ixx="0.0182856182281" ixy="0.0" ixz="0.0" iyy="0.00621358421175" iyz="-0.00472844221905" izz="0.0161514346309" />
      </inertial>

      <visual>
        <geometry>
          <mesh filename="package://${description_pkg}/meshes/panda_arm/visual/link2.dae"/>
        </geometry>
        <material name="">
          <color rgba="1 1 1 1"/>
        </material>        
      </visual>

      <collision>
        <geometry>
          <mesh filename="package://${description_pkg}/meshes/panda_arm/collision/${collision_folder}/link2.stl"/>
        </geometry>
      </collision>
    </link>

    <joint name="${robot_name}_joint3" type="revolute">
      <parent link="${robot_name}_link2"/>
      <child link="${robot_name}_link3"/>
      <origin rpy="${pi/2} 0 0" xyz="0 -0.316 0"/>
      <axis xyz="0 0 1"/>
      <limit lower="${-165 * pi / 180}" upper="${165 * pi / 180}"
             effort="${max_effort}" velocity="${124 * pi / 180}" />
      <safety_controller soft_lower_limit="${-160 * pi / 180}"
                         soft_upper_limit="${160 * pi / 180}"
                         k_position="${safety_controller_k_pos}"
                         k_velocity="${safety_controller_k_vel}"/>
      <dynamics damping="${joint_damping}"/>
    </joint>

    <link name="${robot_name}_link3">
      <inertial>
        <mass value="2.38" />
        <origin xyz="0.0469893 0.0316374 -0.031704" rpy="0 0 0" />
        <inertia ixx="0.00771376630908" ixy="-0.00248490625138" ixz="-0.00332147581033" iyy="0.00989108008727" iyz="-0.00217796151484" izz="0.00811723558464" />
      </inertial>

      <visual>
        <geometry>
          <mesh filename="package://${description_pkg}/meshes/panda_arm/visual/link3.dae"/>
        </geometry>
        <material name="">
          <color rgba="1 1 1 1"/>
        </material>
      </visual>

      <collision>
        <geometry>
          <mesh filename="package://${description_pkg}/meshes/panda_arm/collision/${collision_folder}/link3.stl"/>
        </geometry>
      </collision>
    </link>

    <joint name="${robot_name}_joint4" type="revolute">
      <parent link="${robot_name}_link3"/>
      <child link="${robot_name}_link4"/>
      <origin rpy="${pi/2} 0 0" xyz="0.0825 0 0"/>
      <axis xyz="0 0 1"/>
      <limit lower="${-176 * pi / 180}" upper="${-4 * pi / 180}"
             effort="${max_effort}" velocity="${124 * pi / 180}" />
      <safety_controller soft_lower_limit="${-173 * pi / 180}"
                         soft_upper_limit="${-1 * pi / 180}"
                         k_position="${safety_controller_k_pos}"
                         k_velocity="${safety_controller_k_vel}"/>
      <dynamics damping="${joint_damping}"/>
    </joint>

    <link name="${robot_name}_link4">
      <inertial>
        <mass value="2.38" />
        <origin xyz="-0.0360446 0.0336853 0.031882" rpy="0 0 0" />
        <inertia ixx="0.00799663881132" ixy="0.00347095570217" ixz="-0.00241222942995" iyy="0.00825390705278" iyz="0.00235774044121" izz="0.0102515004345" />
      </inertial>

      <visual>
        <geometry>
          <mesh filename="package://${description_pkg}/meshes/panda_arm/visual/link4.dae"/>
        </geometry>
        <material name="">
          <color rgba="1 1 1 1"/>
        </material>        
      </visual>

      <collision>
        <geometry>
          <mesh filename="package://${description_pkg}/meshes/panda_arm/collision/${collision_folder}/link4.stl"/>
        </geometry>
      </collision>
    </link>

    <joint name="${robot_name}_joint5" type="revolute">
      <parent link="${robot_name}_link4"/>
      <child link="${robot_name}_link5"/>
      <origin rpy="${-pi/2} 0 0" xyz="-0.0825 0.384 0"/>
      <axis xyz="0 0 1"/>
      <limit lower="${-169 * pi / 180}" upper="${169 * pi / 180}"
             effort="${max_effort}" velocity="${140 * pi / 180}" />
      <safety_controller soft_lower_limit="${-167 * pi / 180}"
                         soft_upper_limit="${167 * pi / 180}"
                         k_position="${safety_controller_k_pos}"
                         k_velocity="${safety_controller_k_vel}"/>
      <dynamics damping="${joint_damping}"/>
    </joint>

    <link name="${robot_name}_link5">
      <inertial>
        <mass value="2.74" />
        <origin xyz="0 0.0610427 -0.104176" rpy="0 0 0" />
        <inertia ixx="0.030371374513" ixy="6.50283587108e-07" ixz="-1.05129179916e-05" iyy="0.0288752887402" iyz="-0.00775653445787" izz="0.00444134056164" />
      </inertial>

      <visual>
        <geometry>
          <mesh filename="package://${description_pkg}/meshes/panda_arm/visual/link5.dae"/>
        </geometry>
        <material name="">
          <color rgba="1 1 1 1"/>
        </material>        
      </visual>
      <collision>
        <geometry>
          <mesh filename="package://${description_pkg}/meshes/panda_arm/collision/${collision_folder}/link5.stl"/>
        </geometry>
      </collision>
    </link>

    <joint name="${robot_name}_joint6" type="revolute">
      <parent link="${robot_name}_link5"/>
      <child link="${robot_name}_link6"/>
      <origin rpy="${pi/2} 0 0" xyz="0 0 0"/>
      <axis xyz="0 0 1"/>
      <limit lower="${-1 * pi / 180}" upper="${215 * pi / 180}"
             effort="${max_effort}" velocity="${149 * pi / 180}" />
      <safety_controller soft_lower_limit="${2 * pi / 180}"
                         soft_upper_limit="${212 * pi / 180}"
                         k_position="${safety_controller_k_pos}"
                         k_velocity="${safety_controller_k_vel}"/>
      <dynamics damping="${joint_damping}"/>
    </joint>

    <link name="${robot_name}_link6">
      <inertial>
        <mass value="1.55" />
        <origin xyz="0.0510509 0.009108 0.0106343" rpy="0 0 0" />
        <inertia ixx="0.00303336450376" ixy="-0.000437276865508" ixz="0.000629257294877" iyy="0.00404479911567" iyz="0.000130472021025" izz="0.00558234286039" />
      </inertial>

      <visual>
        <geometry>
          <mesh filename="package://${description_pkg}/meshes/panda_arm/visual/link6.dae"/>
        </geometry>
        <material name="">
          <color rgba="1 1 1 1"/>
        </material>        
      </visual>

      <collision>
        <geometry>
          <mesh filename="package://${description_pkg}/meshes/panda_arm/collision/${collision_folder}/link6.stl"/>
        </geometry>
      </collision>
    </link>

    <joint name="${robot_name}_joint7" type="revolute">
      <parent link="${robot_name}_link6"/>
      <child link="${robot_name}_link7"/>
      <origin rpy="${pi/2} 0 0" xyz="0.088 0 0"/>
      <axis xyz="0 0 1"/>
      <limit lower="${-169 * pi / 180}" upper="${169 * pi / 180}"
             effort="${max_effort}" velocity="${149 * pi / 180}" />
      <safety_controller soft_lower_limit="${-166 * pi / 180}"
                         soft_upper_limit="${166 * pi / 180}"
                         k_position="${safety_controller_k_pos}"
                         k_velocity="${safety_controller_k_vel}"/>
      <dynamics damping="${joint_damping}"/>
    </joint>

    <link name="${robot_name}_link7">
      <inertial>
        <mass value="0.54" />
        <origin xyz="0.0109695 0.0107965 0.0650411" rpy="0 0 0" />
        <inertia ixx="0.000888868887021" ixy="-0.00012239074652" ixz="3.98699829666e-05" iyy="0.000888001373233" iyz="-9.33825115206e-05" izz="0.0007176834609" />
      </inertial>

      <visual>
        <geometry>
          <mesh filename="package://${description_pkg}/meshes/panda_arm/visual/link7.dae"/>
        </geometry>
        <material name="">
          <color rgba="1 1 1 1"/>
        </material>        
      </visual>

      <collision>
        <geometry>
          <mesh filename="package://${description_pkg}/meshes/panda_arm/collision/${collision_folder}/link7.stl"/>
        </geometry>
      </collision>
    </link>

    <joint name="${robot_name}_joint8" type="fixed">
      <parent link="${robot_name}_link7"/>
      <child link="${robot_name}_link8"/>
      <origin rpy="0 0 0" xyz="0 0 0.107"/>
    </joint>

    <link name="${robot_name}_link8">
      <inertial>
        <mass value="0.54" />
        <origin xyz="0.0109695 0.0107965 0.0650411" rpy="0 0 0" />
        <inertia ixx="0.000888868887021" ixy="-0.00012239074652" ixz="3.98699829666e-05" iyy="0.000888001373233" iyz="-9.33825115206e-05" izz="0.0007176834609" />
      </inertial>
    </link>

    <!-- <xacro:if value="${not hand_link_name}"> -->
      <joint name="${robot_name}_hand_joint" type="fixed">
        <parent link="${robot_name}_link8"/>
        <child link="${hand_link_name}"/>
        <origin xyz="0 0 0" rpy="0 0 ${-pi/4}"/>
      </joint>
    <!-- </xacro:if> -->

    <!--Extensions -->
    <xacro:panda_gazebo robot_name="${robot_name}" />
    <xacro:panda_transmission hardware_interface="${hardware_interface}"/>

  </xacro:macro>

</robot>
